<?xml version="1.0"?>

<sdf version='1.6'>
<!-- Basic model of the 16' WAM-V USV -->
<model name="wam-v">
<!--  <static>true</static>-->
  <link name="base_link">
    <inertial>
      <mass>180.0</mass>
      <inertia>
        <ixx>120.0</ixx>
        <ixy>0.0</ixy>
        <ixz>0.0</ixz>
        <iyy>393</iyy>
        <iyz>0.0</iyz>
        <izz>446.0</izz>
      </inertia>
    </inertial>

    <visual name="base_visual">
      <geometry>
        <mesh><uri>meshes/WAM-V-Base.dae</uri></mesh>
      </geometry>
    </visual>

    <!-- Top base -->
    <collision name="top_base">
      <pose>0 -0 1.25 0 0 0</pose>
      <geometry>
        <box><size>1.85 1 0.1" </size></box>
      </geometry>
    </collision>

    <!-- left base -->
    <collision name="left_float">
      <pose>-0.4 1.03 0.2 0 1.57 0 </pose>
      <geometry>
        <cylinder><length>4</length><radius>0.2</radius></cylinder>
      </geometry>
    </collision>
    <collision name="left_mid_float">
      <pose>1.85 1.03 0.3 0 1.38 0</pose>
      <geometry>
        <cylinder><length>0.5</length><radius>0.17</radius></cylinder>
      </geometry>
    </collision>
    <collision name="left_front_float">
      <pose>2.3 1.03 0.4 0 1.3 0</pose>
      <geometry>
        <cylinder><length>0.45</length><radius>0.12</radius></cylinder>
      </geometry>
    </collision>

    <!-- right base -->
    <collision name="right_float">
      <pose>-0.4 -1.03 0.2 0 1.57 0 </pose>
      <geometry>
        <cylinder><length>4</length><radius>0.2</radius></cylinder>
      </geometry>
    </collision>
    <collision name="right_mid_float">
      <pose>1.85 -1.03 0.3 0 1.38 0</pose>
      <geometry>
        <cylinder><length>0.5</length><radius>0.17</radius></cylinder>
      </geometry>
    </collision>
    <collision name="right_front_float">
      <pose>2.3 -1.03 0.4 0 1.3 0</pose>
      <geometry>
        <cylinder><length>0.45</length><radius>0.12</radius></cylinder>
      </geometry>
    </collision>
  </link>

  <!-- left engine and thruster -->
  <link name="left_engine_link">
    <pose>-2.373776 1.027135 0.318237 0 0 0</pose>
    <visual name ="left_engine_visual">
      <geometry>
        <mesh><uri>meshes/engine.dae</uri></mesh>
      </geometry>
    </visual>
    <collision name="left_engine_vertical_axis_collision">
      <pose>-0.16 0 -0.24 0 0 0</pose>
      <geometry>
        <box><size>0.2 0.15 0.83</size></box>
      </geometry>
    </collision>
    <collision name="left_engine_rear_end_collision">
      <pose>-0.34 0 0.12 0 0 0</pose>
      <geometry>
        <box><size>0.12 0.15 0.12</size></box>
      </geometry>
    </collision>
    <inertial>
      <mass>15.0</mass>
      <inertia>
        <ixx>0.889245</ixx>
        <ixy>0.0</ixy>
        <ixz>0.0</ixz>
        <iyy>0.811125</iyy>
        <iyz>0.0</iyz>
        <izz>0.078125</izz>
      </inertia>
    </inertial>
  </link>
  <link name="left_propeller_link">
    <pose>-2.651932 1.027135 -0.191134 0 0 0</pose>
    <visual name ="left_properller_visual">
      <geometry>
        <mesh><uri>meshes/propeller.dae</uri></mesh>
      </geometry>
    </visual>
    <collision name="left_propeller_collision">
      <pose>-0.08 0 0 0 1.57 0</pose>
      <geometry>
        <cylinder><length>0.18</length><radius>0.24</radius></cylinder>
      </geometry>
    </collision>
    <inertial>
      <mass>0.5</mass>
      <inertia>
        <ixx>0.008545</ixx>
        <ixy>0.0</ixy>
        <ixz>0.0</ixz>
        <iyy>0.008545</iyy>
        <iyz>0.0</iyz>
        <izz>0.0144</izz>
      </inertia>
    </inertial>
  </link>

  <joint name="left_chasis_engine_joint" type="revolute">
<!--    <pose>-2.373776 1.027135 0.318237 0 0 0</pose>-->
    <axis>
      <xyz>0 0 1</xyz>
      <limit>
        <lower>-3.14</lower>
        <upper>3.14</upper>
        <effort>10</effort>
        <velocity>10</velocity>
      </limit>
    </axis>
    <parent>base_link</parent>
    <child>left_engine_link</child>
  </joint>

  <joint name="left_engine_propeller_joint" type="revolute">
<!--    <pose>-0.278156 0 -0.509371 0 0 0</pose>-->
    <axis>
      <xyz>1 0 0</xyz>
      <limit>
        <effort>100</effort>
        <velocity>100</velocity>
      </limit>
      <dynamics>
        <friction>0.05</friction>
        <damping>0.05</damping>
      </dynamics>
    </axis>
    <parent>left_engine_link</parent>
    <child>left_propeller_link</child>
  </joint>

  <!-- right engine and thruster -->
  <link name="right_engine_link">
    <pose>-2.373776 -1.027135 0.318237 0 0 0</pose>
    <visual name ="right_engine_visual">
      <geometry>
        <mesh><uri>meshes/engine.dae</uri></mesh>
      </geometry>
    </visual>
    <collision name="right_engine_vertical_axis_collision">
      <pose>-0.16 0 -0.24 0 0 0</pose>
      <geometry>
        <box><size>0.2 0.15 0.83</size></box>
      </geometry>
    </collision>
    <collision name="right_engine_rear_end_collision">
      <pose>-0.34 0 0.12 0 0 0</pose>
      <geometry>
        <box><size>0.12 0.15 0.12</size></box>
      </geometry>
    </collision>
    <inertial>
      <mass>15.0</mass>
      <inertia>
        <ixx>0.889245</ixx>
        <ixy>0.0</ixy>
        <ixz>0.0</ixz>
        <iyy>0.811125</iyy>
        <iyz>0.0</iyz>
        <izz>0.078125</izz>
      </inertia>
    </inertial>
  </link>
  <link name="right_propeller_link">
    <pose>-2.651932 -1.027135 -0.191134 0 0 0</pose>
    <visual name ="right_properller_visual">
      <geometry>
        <mesh><uri>meshes/propeller.dae</uri></mesh>
      </geometry>
    </visual>
    <collision name="right_propeller_collision">
      <pose>-0.08 0 0 0 1.57 0</pose>
      <geometry>
        <cylinder><length>0.18</length><radius>0.24</radius></cylinder>
      </geometry>
    </collision>
    <inertial>
      <mass>0.5</mass>
      <inertia>
        <ixx>0.008545</ixx>
        <ixy>0.0</ixy>
        <ixz>0.0</ixz>
        <iyy>0.008545</iyy>
        <iyz>0.0</iyz>
        <izz>0.0144</izz>
      </inertia>
    </inertial>
  </link>

  <joint name="right_chasis_engine_joint" type="revolute">
<!--    <pose>-2.373776 -1.027135 0.318237 0 0 0</pose>-->
    <axis>
      <xyz>0 0 1</xyz>
      <limit>
        <lower>-3.14</lower>
        <upper>3.14</upper>
        <effort>10</effort>
        <velocity>10</velocity>
      </limit>
    </axis>
    <parent>base_link</parent>
    <child>right_engine_link</child>
  </joint>

  <joint name="right_engine_propeller_joint" type="revolute">
<!--    <pose>-0.278156 0 -0.509371 0 0 0</pose>-->
    <axis>
      <xyz>1 0 0</xyz>
      <limit>
        <effort>100</effort>
        <velocity>100</velocity>
      </limit>
      <dynamics>
        <friction>0.05</friction>
        <damping>0.05</damping>
      </dynamics>
    </axis>
    <parent>right_engine_link</parent>
    <child>right_propeller_link</child>
  </joint>

<!--  <plugin
    filename="ignition-gazebo-thruster-system"
    name="ignition::gazebo::systems::Thruster">
    <namespace>usv_left</namespace>
    <joint_name>left_engine_properller_joint</joint_name>
    <thrust_coefficient>0.004422</thrust_coefficient>
    <fluid_density>1000</fluid_density>
    <propeller_diameter>0.2</propeller_diameter>
  </plugin>

  <plugin
    filename="ignition-gazebo-thruster-system"
    name="ignition::gazebo::systems::Thruster">
    <namespace>usv_right</namespace>
    <joint_name>right_engine_properller_joint</joint_name>
    <thrust_coefficient>0.004422</thrust_coefficient>
    <fluid_density>1000</fluid_density>
    <propeller_diameter>0.2</propeller_diameter>
  </plugin>
-->

  <plugin
  filename="ignition-gazebo-hydrodynamics-system"
  name="ignition::gazebo::systems::Hydrodynamics">
      <link_name>base_link</link_name>
      <xDotU>-4.876161</xDotU>
      <yDotV>-126.324739</yDotV>
      <zDotW>-126.324739</zDotW>
      <kDotP>0</kDotP>
      <mDotQ>-33.46</mDotQ>
      <nDotR>-33.46</nDotR>
      <xUU>-6.2282</xUU>
      <xU>0</xU>
      <yVV>-601.27</yVV>
      <yV>0</yV>
      <zWW>-601.27</zWW>
      <zW>0</zW>
      <kPP>-0.1916</kPP>
      <kP>0</kP>
      <mQQ>-632.698957</mQQ>
      <mQ>0</mQ>
      <nRR>-632.698957</nRR>
      <nR>0</nR>
  </plugin>

</model>
</sdf>
